Workbook
Name ANO: #REF!
Name DIASLETIVOS: #REF!
Name DiasTarefa: '[1]Ensino Fundamental - NOVO (2)'!$I$69:$J$71
Name domingo: #REF!
Name FERIADOS: #REF!
Name FÉRIAS: #REF!
Name sabado: #REF!

Sheet DADOS
A6: PÁGINA | B6: DIAS LETIVOS/OUTROS | C6: DIA LETIVO MARQUE "DL" NÃO LETIVO "NL" | D6: =IF(C6="DL","DIA LETIVO: ",IF(C6="DNP", "DIA NÃO PRESENCIAL: ","")) | E6: DATA
A7: 1 | B7: FÉRIAS ESCOLARES - 02/01 a 31/01 | C7: NL | D7: =IF(C7="DL","DIA LETIVO: Nº ",IF(C7="DNP", "DIA NÃO PRESENCIAL: ","")) | E7: 45659
A8: 2 | B8: Acolhimento dos Funcionários / Jornada Pedagógica | C8: NL | D8: =IF(C8="DL","DIA LETIVO: Nº ",IF(C8="DNP", "DIA NÃO PRESENCIAL: ","")) | E8: 45691
A9: 3 | B9: 1 | C9: DL | D9: =IF(C9="DL","DIA LETIVO: Nº ",IF(C9="DNP", "DIA NÃO PRESENCIAL: ","")) -> DIA LETIVO: Nº | E9: 45692
A10: 4 | B10: =SUM(B9+1) -> 2 | C10: DL | D10: =IF(C10="DL","DIA LETIVO: Nº ",IF(C10="DNP", "DIA NÃO PRESENCIAL: ","")) -> DIA LETIVO: Nº | E10: 45693
A11: 5 | B11: =SUM(B10+1) -> 3 | C11: DL | D11: =IF(C11="DL","DIA LETIVO: Nº ",IF(C11="DNP", "DIA NÃO PRESENCIAL: ","")) -> DIA LETIVO: Nº | E11: 45694
A12: 6 | B12: =SUM(B11+1) -> 4 | C12: DL | D12: =IF(C12="DL","DIA LETIVO: Nº ",IF(C12="DNP", "DIA NÃO PRESENCIAL: ","")) -> DIA LETIVO: Nº | E12: 45695
A13: 7 | B13: =SUM(B12+1) -> 5 | C13: DL | D13: =IF(C13="DL","DIA LETIVO: Nº ",IF(C13="DNP", "DIA NÃO PRESENCIAL: ","")) -> DIA LETIVO: Nº | E13: 45698
A14: 8 | B14: =SUM(B13+1) -> 6 | C14: DL | D14: =IF(C14="DL","DIA LETIVO: Nº ",IF(C14="DNP", "DIA NÃO PRESENCIAL: ","")) -> DIA LETIVO: Nº | E14: 45699
A15: 9 | B15: =SUM(B14+1) -> 7 | C15: DL | D15: =IF(C15="DL","DIA LETIVO: Nº ",IF(C15="DNP", "DIA NÃO PRESENCIAL: ","")) -> DIA LETIVO: Nº | E15: 45700
A16: 10 | B16: =SUM(B15+1) -> 8 | C16: DL | D16: =IF(C16="DL","DIA LETIVO: Nº ",IF(C16="DNP", "DIA NÃO PRESENCIAL: ","")) -> DIA LETIVO: Nº | E16: 45701
A17: 11 | B17: =SUM(B16+1) -> 9 | C17: DL | D17: =IF(C17="DL","DIA LETIVO: Nº ",IF(C17="DNP", "DIA NÃO PRESENCIAL: ","")) -> DIA LETIVO: Nº | E17: 45702
A18: 12 | B18: =SUM(B17+1) -> 10 | C18: DL | D18: =IF(C18="DL","DIA LETIVO: Nº ",IF(C18="DNP", "DIA NÃO PRESENCIAL: ","")) -> DIA LETIVO: Nº | E18: 45705
A19: 13 | B19: =SUM(B18+1) -> 11 | C19: DL | D19: =IF(C19="DL","DIA LETIVO: Nº ",IF(C19="DNP", "DIA NÃO PRESENCIAL: ","")) -> DIA LETIVO: Nº | E19: 45706
A20: 14 | B20: =SUM(B19+1) -> 12 | C20: DL | D20: =IF(C20="DL","DIA LETIVO: Nº ",IF(C20="DNP", "DIA NÃO PRESENCIAL: ","")) -> DIA LETIVO: Nº | E20: 45707
A21: 15 | B21: =SUM(B20+1) -> 13 | C21: DL | D21: =IF(C21="DL","DIA LETIVO: Nº ",IF(C21="DNP", "DIA NÃO PRESENCIAL: ","")) -> DIA LETIVO: Nº | E21: 45708
... A72: 66 | B72: =SUM(B71+1) -> 64 | C72: DL | D72: =IF(C72="DL","DIA LETIVO: Nº ",IF(C72="DNP", "DIA NÃO PRESENCIAL: ","")) -> DIA LETIVO: Nº | E72: 45792
A73: 67 | B73: CONSELHO DE CLASSE 1º TRIMESTRE | C73: NL | D73: =IF(C73="DL","DIA LETIVO: Nº ",IF(C73="DNP", "DIA NÃO PRESENCIAL: ","")) | E73: 45793
A74: 68 | B74: =SUM(B72+1) -> 65 | C74: DL | D74: =IF(C74="DL","DIA LETIVO: Nº ",IF(C74="DNP", "DIA NÃO PRESENCIAL: ","")) -> DIA LETIVO: Nº | E74: 45796
A75: 69 | B75: =SUM(B74+1) -> 66 | C75: DL | D75: =IF(C75="DL","DIA LETIVO: Nº ",IF(C75="DNP", "DIA NÃO PRESENCIAL: ","")) -> DIA LETIVO: Nº | E75: 45797
A76: 70 | B76: =SUM(B75+1) -> 67 | C76: DL | D76: =IF(C76="DL","DIA LETIVO: Nº ",IF(C76="DNP", "DIA NÃO PRESENCIAL: ","")) -> DIA LETIVO: Nº | E76: 45798
A77: 71 | B77: =SUM(B76+1) -> 68 | C77: DL | D77: =IF(C77="DL","DIA LETIVO: Nº ",IF(C77="DNP", "DIA NÃO PRESENCIAL: ","")) -> DIA LETIVO: Nº | E77: 45799
A78: 72 | B78: =SUM(B77+1) -> 69 | C78: DL | D78: =IF(C78="DL","DIA LETIVO: Nº ",IF(C78="DNP", "DIA NÃO PRESENCIAL: ","")) -> DIA LETIVO: Nº | E78: 45800
A79: 73 | B79: =SUM(B78+1) -> 70 | C79: DL | D79: =IF(C79="DL","DIA LETIVO: Nº ",IF(C79="DNP", "DIA NÃO PRESENCIAL: ","")) -> DIA LETIVO: Nº | E79: 45803
A80: 74 | B80: =SUM(B79+1) -> 71 | C80: DL | D80: =IF(C80="DL","DIA LETIVO: Nº ",IF(C80="DNP", "DIA NÃO PRESENCIAL: ","")) -> DIA LETIVO: Nº | E80: 45804
A81: 75 | B81: =SUM(B80+1) -> 72 | C81: DL | D81: =IF(C81="DL","DIA LETIVO: Nº ",IF(C81="DNP", "DIA NÃO PRESENCIAL: ","")) -> DIA LETIVO: Nº | E81: 45805
A82: 76 | B82: =SUM(B81+1) -> 73 | C82: DL | D82: =IF(C82="DL","DIA LETIVO: Nº ",IF(C82="DNP", "DIA NÃO PRESENCIAL: ","")) -> DIA LETIVO: Nº | E82: 45806
A83: 77 | B83: =SUM(B82+1) -> 74 | C83: DL | D83: =IF(C83="DL","DIA LETIVO: Nº ",IF(C83="DNP", "DIA NÃO PRESENCIAL: ","")) -> DIA LETIVO: Nº | E83: 45807
A84: 78 | B84: =SUM(B83+1) -> 75 | C84: DL | D84: =IF(C84="DL","DIA LETIVO: Nº ",IF(C84="DNP", "DIA NÃO PRESENCIAL: ","")) -> DIA LETIVO: Nº | E84: 45810
A85: 79 | B85: =SUM(B84+1) -> 76 | C85: DL | D85: =IF(C85="DL","DIA LETIVO: Nº ",IF(C85="DNP", "DIA NÃO PRESENCIAL: ","")) -> DIA LETIVO: Nº | E85: 45811
A86: 80 | B86: =SUM(B85+1) -> 77 | C86: DL | D86: =IF(C86="DL","DIA LETIVO: Nº ",IF(C86="DNP", "DIA NÃO PRESENCIAL: ","")) -> DIA LETIVO: Nº | E86: 45812
... A111: 105 | B111: =SUM(B110+1) -> 102 | C111: DL | D111: =IF(C111="DL","DIA LETIVO: Nº ",IF(C111="DNP", "DIA NÃO PRESENCIAL: ","")) -> DIA LETIVO: Nº | E111: 45849
A112: 106 | B112: FÉRIAS ESCOLARES - 15 a 23 de julho | C112: NL | D112: =IF(C112="DL","DIA LETIVO: Nº ",IF(C112="DNP", "DIA NÃO PRESENCIAL: ","")) | E112: 45852
A113: 107 | B113: Jornada Pedagógica | C113: NL | D113: =IF(C113="DL","DIA LETIVO: Nº ",IF(C113="DNP", "DIA NÃO PRESENCIAL: ","")) | E113: 45861
A114: 108 | B114: Jornada Pedagógica | C114: NL | D114: =IF(C114="DL","DIA LETIVO: Nº ",IF(C114="DNP", "DIA NÃO PRESENCIAL: ","")) | E114: 45862
A115: 109 | B115: Jornada Pedagógica | C115: NL | D115: =IF(C115="DL","DIA LETIVO: Nº ",IF(C115="DNP", "DIA NÃO PRESENCIAL: ","")) | E115: 45863
A116: 110 | B116: =SUM(B111+1) -> 103 | C116: DL | D116: =IF(C116="DL","DIA LETIVO: Nº ",IF(C116="DNP", "DIA NÃO PRESENCIAL: ","")) -> DIA LETIVO: Nº | E116: 45866
A117: 111 | B117: =SUM(B116+1) -> 104 | C117: DL | D117: =IF(C117="DL","DIA LETIVO: Nº ",IF(C117="DNP", "DIA NÃO PRESENCIAL: ","")) -> DIA LETIVO: Nº | E117: 45867
A118: 112 | B118: =SUM(B117+1) -> 105 | C118: DL | D118: =IF(C118="DL","DIA LETIVO: Nº ",IF(C118="DNP", "DIA NÃO PRESENCIAL: ","")) -> DIA LETIVO: Nº | E118: 45868
A119: 113 | B119: =SUM(B118+1) -> 106 | C119: DL | D119: =IF(C119="DL","DIA LETIVO: Nº ",IF(C119="DNP", "DIA NÃO PRESENCIAL: ","")) -> DIA LETIVO: Nº | E119: 45869
...

Sheet MENU
A1: LIVRO DE PONTO
A4: ENDEREÇO
A5: CEP, TELEFONE E EMAIL
E8: TURNO: | F8: MATUTINO
A10: Nº | B10: SIT. FUN. | C10: MAT. | D10: Nome do professor | E10: Disciplinas | G10: Hor. | H10: Hor. | I10: Turmas/ Aulas | N10: Assinaturas
G11: Entr. | H11: Saída | I11: 1ª | J11: 2ª | K11: 3ª | L11: 4ª | M11: 5ª
A12: =ROW()-10 -> 2
A13: =ROW()-10 -> 3
A14: =ROW()-10 -> 4
A15: =ROW()-10 -> 5
A16: =ROW()-10 -> 6
A17: =ROW()-10 -> 7
A18: =ROW()-10 -> 8
A19: =ROW()-10 -> 9
A20: =ROW()-10 -> 10
A21: =ROW()-10 -> 11
A22: =ROW()-10 -> 12
A23: =ROW()-10 -> 13
... A29: =ROW()-10 -> 19
A31: OBS:
A34: COORDENADOR (A):
A36: DIRETOR (A):
A38: SIT. FUN. (SITUAÇÃO FUNCIONAL)
A39: LEGENDA:
A40: EST.= ESTATUTÁRIO
A41: DT= DESIGNAÇÃO TEMPORARIA

Sheet LIVRO DE PONTO
B1: =IF(MENU!A2="","",MENU!A2) | O1: =IF(MENU!N2="","",MENU!N2)
B3: =IF(MENU!A4="","",MENU!A4) -> ENDEREÇO
B4: =IF(MENU!A5="","",MENU!A5) -> CEP, TELEFONE E EMAIL
B7: =CONCATENATE(VLOOKUP('LIVRO DE PONTO'!O35,DADOS!A7:E227,4,0),VLOOKUP('LIVRO DE PONTO'!O35,DADOS!A7:E227,2,0)) -> FÉRIAS ESCOLARES - 02/01 a 31/01 | H7: =CONCATENATE("TURNO: ",MENU!F8) -> TURNO: MATUTINO | L7: Fundão - ES, | O7: =VLOOKUP('LIVRO DE PONTO'!O35,DADOS!A7:E227,5,0) -> 45659
B9: Nº | C9: SIT. FUN. | D9: Nome do (a) professor (a) | E9: MAT. | F9: Turma/Componente Curricular | H9: Hor. | I9: Hor. | J9: Turma/Componente Curricular | O9: Assinaturas
H10: Entr. | I10: Saída | J10: 1ª | K10: 2ª | L10: 3ª | M10: 4ª | N10: 5ª
B11: =ROW()-10 -> 1
B12: =ROW()-10 -> 2
B13: =ROW()-10 -> 3
B14: =ROW()-10 -> 4
B15: =ROW()-10 -> 5
B16: =ROW()-10 -> 6
B17: =ROW()-10 -> 7
B18: =ROW()-10 -> 8
B19: =ROW()-10 -> 9
B20: =ROW()-10 -> 10
B21: =ROW()-10 -> 11
B22: =ROW()-10 -> 12
... B28: =ROW()-10 -> 18
B30: OBS.:
B33: =CONCATENATE(MENU!A34,MENU!D34) -> COORDENADOR (A):
B35: =CONCATENATE(MENU!A36,MENU!D36) -> DIRETOR (A): | O35: 1
